Workbook
Name Status: Variables!$A$2:$A$7

Sheet Test Metrics Summary
B3: Compatibility Testing - Test Metrics Summary
B5: Project: | C5: Learning Journey Assistant (Capstone project, Team Smart Stack)
B6: Website tested: | C6: https://learning-journey-app.onrender.com
B7: Pages tested: | C7: Login page and Student Dashboard
B8: Tester: | C8: Ritik Rayamajhi
B9: Date tested: | C9: 46300
B10: How I tested: | C10: I used the 47-item compatibility checklist on 5 different systems (3 desktop browsers and 2 phones). I wrote a Playwright script that opens the app in each browser, does the steps for each checklist item and times how long each test takes. Each system has its own sheet with the full results. My first run found 3 defects; after they were fixed I ran all the tests again. The results and times in this workbook are from that final run.
B12: Metrics per system
B13: System | C13: Environment | D13: Tests executed | E13: Passed | F13: Failed | G13: Not run | H13: Not applicable | I13: Total time (sec) | J13: Average time per test (sec) | K13: Pass rate | L13: Failure rate
B14: Chrome (macOS) | C14: MacBook, macOS 26.5.2, Google Chrome 154.0.8037.95, screen 1440x900 | D14: ='Chrome (macOS)'!F66 -> 21 | E14: ='Chrome (macOS)'!F67 -> 21 | F14: ='Chrome (macOS)'!F68 -> 0 | G14: ='Chrome (macOS)'!F69 -> 1 | H14: ='Chrome (macOS)'!F70 -> 25 | I14: ='Chrome (macOS)'!F71 -> 71.27 | J14: ='Chrome (macOS)'!F72 -> 3.3938095 | K14: ='Chrome (macOS)'!F73 -> 1 | L14: ='Chrome (macOS)'!F74 -> 0
B15: Firefox (macOS) | C15: MacBook, macOS 26.5.2, Mozilla Firefox 155.0 (Playwright build), screen 1440x900 | D15: ='Firefox (macOS)'!F66 -> 21 | E15: ='Firefox (macOS)'!F67 -> 21 | F15: ='Firefox (macOS)'!F68 -> 0 | G15: ='Firefox (macOS)'!F69 -> 1 | H15: ='Firefox (macOS)'!F70 -> 25 | I15: ='Firefox (macOS)'!F71 -> 72.58 | J15: ='Firefox (macOS)'!F72 -> 3.4561905 | K15: ='Firefox (macOS)'!F73 -> 1 | L15: ='Firefox (macOS)'!F74 -> 0
B16: Safari (macOS) | C16: MacBook, macOS 26.5.2, Safari engine WebKit 26.6 (Playwright build), screen 1440x900 | D16: ='Safari (macOS)'!F66 -> 21 | E16: ='Safari (macOS)'!F67 -> 21 | F16: ='Safari (macOS)'!F68 -> 0 | G16: ='Safari (macOS)'!F69 -> 1 | H16: ='Safari (macOS)'!F70 -> 25 | I16: ='Safari (macOS)'!F71 -> 70.98 | J16: ='Safari (macOS)'!F72 -> 3.38 | K16: ='Safari (macOS)'!F73 -> 1 | L16: ='Safari (macOS)'!F74 -> 0
B17: iPhone 13 (Safari) | C17: Apple iPhone 13 emulator (iOS Safari, WebKit 26.6) on macOS, screen 390x664, touch on | D17: ='iPhone 13 (Safari)'!F66 -> 20 | E17: ='iPhone 13 (Safari)'!F67 -> 20 | F17: ='iPhone 13 (Safari)'!F68 -> 0 | G17: ='iPhone 13 (Safari)'!F69 -> 1 | H17: ='iPhone 13 (Safari)'!F70 -> 26 | I17: ='iPhone 13 (Safari)'!F71 -> 67.82 | J17: ='iPhone 13 (Safari)'!F72 -> 3.391 | K17: ='iPhone 13 (Safari)'!F73 -> 1 | L17: ='iPhone 13 (Safari)'!F74 -> 0
B18: Pixel 7 (Chrome) | C18: Google Pixel 7 emulator (Android, Chrome 154.0.8037.95) on macOS, screen 412x839, touch on | D18: ='Pixel 7 (Chrome)'!F66 -> 20 | E18: ='Pixel 7 (Chrome)'!F67 -> 20 | F18: ='Pixel 7 (Chrome)'!F68 -> 0 | G18: ='Pixel 7 (Chrome)'!F69 -> 1 | H18: ='Pixel 7 (Chrome)'!F70 -> 26 | I18: ='Pixel 7 (Chrome)'!F71 -> 65.05 | J18: ='Pixel 7 (Chrome)'!F72 -> 3.2525 | K18: ='Pixel 7 (Chrome)'!F73 -> 1 | L18: ='Pixel 7 (Chrome)'!F74 -> 0
B19: All systems | C19: Totals across the 5 systems | D19: =SUM(D14:D18) -> 103 | E19: =SUM(E14:E18) -> 103 | F19: =SUM(F14:F18) -> 0 | G19: =SUM(G14:G18) -> 5 | H19: =SUM(H14:H18) -> 127 | I19: =SUM(I14:I18) -> 347.7 | J19: =IFERROR(I19/D19,0) -> 3.3757282 | K19: =IFERROR(E19/D19,0) -> 1 | L19: =IFERROR(F19/D19,0) -> 0
B21: What the numbers mean
B22: Tests executed | C22: Tests that I actually ran and that got a Pass or Fail. "Not applicable" means the app doesn't have that feature (e.g. videos, file upload). "Not run" means I couldn't test it on this system.
B23: Total time | C23: Adds up the time of every test I ran on that system (the "Time Taken (sec)" column on each sheet).
B24: Average time per test | C24: Total time ÷ Tests executed.
B25: Pass rate | C25: Passed ÷ Tests executed.
B26: Failure rate | C26: Failed ÷ Tests executed. Pass rate + Failure rate = 100%.
B27: First test run | C27: Before the fixes, my first run had 11 failed tests out of 103 (overall pass rate 89.3%) caused by the 3 defects below. After the fixes every test passed.
B28: Note on times | C28: The times come from the automated script, so they are much faster than doing it by hand. Each time includes opening the page and logging in for that test.
B31: Defects found (first run) and their status
B32: Defect ID | C32: Details | H32: Severity | I32: Checklist ID | J32: Systems affected | K32: Status
B33: DEF-01 | C33: With JavaScript disabled the app shows a blank white page and no message. Expected: a message like "Please enable JavaScript to use this app" (e.g. a <noscript> tag in layout.tsx). | H33: Minor | I33: 10 | J33: All 5 systems | K33: Fixed: added a message telling users to turn on JavaScript. Retested - Pass
B34: DEF-02 | C34: AI study plan can't be generated: the server returns an error because no GROQ_API_KEY is configured on Render. Same on every system. This is a configuration issue (missing setting), not a bug in the code. | H34: Minor | I34: 30 | J34: All 5 systems | K34: Fixed: GROQ_API_KEY added to the backend on Render. Retested - Pass
B35: DEF-03 | C35: On iPhone at 200% page zoom (very narrow screen, ~195px), the score labels in 'Mastery by learning outcome' overflow the right edge and cause sideways scrolling. Fix: let the label wrap under the outcome text on very small screens. | H35: Minor | I35: 9 | J35: iPhone 13 (Safari) | K35: Fixed: text and score labels now wrap on very narrow screens. Retested - Pass

Sheet Chrome (macOS)
C3: Compatibility Testing Checklist
D5: Test object: | E5: Learning Journey Assistant (https://learning-journey-app.onrender.com) | F5: Name of the system being tested
D6: Test basis: | E6: User stories: a student logs in and views their mastery scores, knowledge gaps, feedback history and AI study plan. Also past experience with similar web apps. | F6: What test design is based on - for example, requirements, epics, user stories, or past experience with similar systems
D7: Page name: | E7: Login page and Student Dashboard | F7: Name of the page or tab being tested
D8: Environment details: | E8: MacBook, macOS 26.5.2, Google Chrome 154.0.8037.95, screen 1440x900. Tests run with a Playwright automation script. | F8: Describe the test environment - e.g. Apple iPhone X running iOS Y, Edge browser version aa.bb
D9: Tester name: | E9: Ritik Rayamajhi | F9: Name of the person performing the testing
D10: Date tested: | E10: 46300 | F10: Date tests were run on
C12: ID | D12: Perspective | E12: Checklist | F12: Result | G12: Comments | H12: Defect ID | I12: Defect Severity | J12: Defect Details | K12: Test Evidence | L12: Time Taken (sec)
C13: 1 | D13: Page structure | E13: Has the correct page template, style sheet and/or structure been used, matching company and project requirements? | F13: Pass | G13: Both pages (login and dashboard) use the same layout: logo at the top, white rounded cards on a light grey background. | K13: Compatibility Testing Evidence/chrome-dashboard.png | L13: 4.45
C14: 2 | D14: Page structure | E14: Do page colours and fonts match company branding? | F14: Pass | G14: We don't have an official brand guide, so I checked the purple colour is the same on all buttons and the logo on both pages. It matched. | L14: 3.67
C15: 3 | D15: Page structure | E15: Does the page description (e.g. in the title bar or tab) correctly reflect the page content? | F15: Pass | G15: The tab title says "Learning Journey Assistant" on both pages, which matches the app name. | L15: 3.68
C16: 4 | D16: Page structure | E16: Have correct and consistent fonts, text sizes and text positions been used, including: - Header - Menu bar - Body/content - Input and output fields - Buttons (e.g. Next/Previous, Submit/Cancel etc.) - Footer | F16: Pass | G16: Header, body text, dropdown, password box and buttons all use the same font (Geist). Headings are bigger and bold, body text is smaller. Nothing overlapped. (No menu bar or footer in our app.) | L16: 4.36
C17: 5 | D17: Page structure | E17: Does the page display correctly across different screen resolutions, including: - High definition (HD) - Recommended display setting (on computer) - Lowest display setting (on computer) - Devices (e.g. mobile, tablet, watch) | F17: Pass | G17: Checked the dashboard at 1920x1080 (HD), 1440x900 (recommended on this Mac) and 1366x768 / 1024x768 (lowest). It looked fine at all of them. Phones are tested on the mobile sheets. | K17: Compatibility Testing Evidence/chrome-resolution-small.png | L17: 4.18
C18: 6 | D18: Page structure | E18: Does the page scroll smoothly without lagging? | F18: Pass | G18: Scrolled from the top to the bottom of the dashboard. It was smooth with no lag (about 61 frames per second). | L18: 4.3
C19: 7 | D19: Page structure | E19: Is the page content viewable without the need for a horizontal scroll bar? (horizontal scrolling is generally not recommended/preferred) | F19: Pass | G19: No horizontal scroll bar on the login page or the dashboard. Everything fits the width of the screen. | L19: 3.81
C20: 8 | D20: Page structure | E20: Do menus function correctly when opened, traversed and activated/clicked, including: - Hamburger menu - Expandable menus - Collapsible menus - Drop down "more information" menus (usually available via an ellipsis …) | F20: Pass | G20: Our app has no hamburger or expandable menus. The only menu is the student dropdown on the login page - I picked all 5 students one by one and each one got selected. | L20: 0.93
C21: 9 | D21: Page structure | E21: Does the page view correctly when using zoom in and out? | F21: Pass | G21: Zoomed in to 200% and out to 50%. The text and bars resized properly and nothing went off the screen. | K21: Compatibility Testing Evidence/chrome-zoom-200.png | L21: 4.27
C22: 10 | D22: Page structure | E22: When JavaScript is turned off, do understandable error messages appear explaining that JavaScript must be enabled to display required content, without any scripts being displayed to on the screen? | F22: Pass | G22: With JavaScript off the page shows: "Learning Journey Assistant Please enable JavaScript in your browser to use this" (This failed in my first test run - see DEF-01. After the fix I retested it and it passed.) | H22: DEF-01 | I22: Minor | J22: With JavaScript disabled the app shows a blank white page and no message. Expected: a message like "Please enable JavaScript to use this app" (e.g. a <noscript> tag in layout.tsx). Fixed: added a message telling users to turn on JavaScript. Retested 05/10/2026: Pass. | K22: After fix: Compatibility Testing Evidence/chrome-javascript-off.png Before fix: Compatibility Testing Evidence/first-run/chrome-javascript-off.png | L22: 1.79
C23: 11 | D23: Images | E23: Are images displayed correctly, including: - Position on the page (alignment, not overlapping fields, content or edge of screen) - Rendering - Resolution - Background (e.g. transparent) - Lazy loading (load on scroll) - No distortion (i.e. correct aspect ratio) - No broken links | F23: Not applicable | G23: Our pages don't have any images. The logo is just the letters "LJ" in a purple box (made with text, not an image).
C24: 12 | D24: Images | E24: Are images suitable for the given content and context? | F24: Not applicable | G24: No images on the login page or dashboard.
C25: 13 | D25: Images | E25: Do images include suitable alternative text? | F25: Not applicable | G25: No images, so there is no alt text to check.
C26: 14 | D26: Images | E26: Do clickable images navigate to the correct location? | F26: Not applicable | G26: No clickable images in the app.
C27: 15 | D27: Images | E27: Do images display correctly when screen is zoomed in and out? | F27: Not applicable | G27: No images. (Zoom for the rest of the page was checked in test 9.)
C28: 16 | D28: Images | E28: Do animated behaviours display correctly (e.g. Giff) | F28: Not applicable | G28: No GIFs or animations in the app.
C29: 17 | D29: Videos | E29: Are videos displayed, positioned and rendered correctly on the page, with the correct thumbnails? | F29: Not applicable | G29: The app doesn't have any videos.
C30: 18 | D30: Videos | E30: Do videos play correctly, including (where required): - Auto play - Click to play - Tap to play - Picture in picture (PiP) | F30: Not applicable | G30: The app doesn't have any videos.
C31: 19 | D31: Videos | E31: Do videos display with the correct defaults (e.g. auto-play, display inline or full screen) | F31: Not applicable | G31: The app doesn't have any videos.
C32: 20 | D32: Videos | E32: Do all videos display suitable captions, including: - Captions that match the video content - Language preferences - Location on screen | F32: Not applicable | G32: The app doesn't have any videos.
C33: 21 | D33: Videos | E33: Can videos be moved to: - Full screen mode - Embedded/inline mode - Press escape from full-screen mode to revert back to inline mode | F33: Not applicable | G33: The app doesn't have any videos.
C34: 22 | D34: Videos | E34: Do video controls work, including: - Play, pause, stop - Fast forward and rewind (including skip X seconds forward/back) - Volume - Mute/unmute - Playback speed (e.g. 0.5x, 1.5x, 2x) - Resume from last position - Download / long-press - Streaming vs. offline view | F34: Not applicable | G34: The app doesn't have any videos.
C35: 23 | D35: Forms | E35: Are all required fields visible on the form? | F35: Pass | G35: The login form shows both fields I need (Student dropdown and Password) and the Sign in button. All visible without scrolling. | K35: Compatibility Testing Evidence/chrome-login.png | L35: 0.96
C36: 24 | D36: Forms | E36: Are all form fields positioned within the boundaries of the form, and not overlapping or truncating, including: - Labels - Single line textboxes - Multi-line textboxes - Dropdown lists - Radio buttons - Checkboxes - Date pickers - Tables - Grids - Menus and submenus - Images - Drag and drop | F36: Pass | G36: Labels, the dropdown, the password box and the button all sit inside the white form box. Nothing overlaps or gets cut off. | L36: 0.92
C37: 25 | D37: Forms | E37: Does tool tip text display correctly for each field, including: - Single line textboxes - Multi-line textboxes - Dropdown lists - Radio buttons - Checkboxes - Date pickers - Tables - Grids - Drag and drop | F37: Not applicable | G37: Our form fields don't have tooltips. Each field has a label above it instead ("Student", "Password").
C38: 26 | D38: Forms | E38: Can data be input into each field correctly, including: - Single line textboxes - Multi-line textboxes - Dropdown lists - Radio buttons - Checkboxes - Date pickers - Tables - Grids - Drag and drop - Copy/paste | F38: Pass | G38: Picked a student from the dropdown and typed letters, numbers and symbols in the password box. Both worked and the password showed as dots. (Didn't test copy/paste because browsers block copying out of password boxes.) | L38: 1
C39: 27 | D39: Forms | E39: When invalid/negative data is input into a field: - Are understandable error messages displayed? - Are error messages displayed at the right time (e.g. when focus leaves the field, or on save)? - Are error messages positioned in the correct location? - Are error validation icons (e.g. ticks, crosses) displayed in the correct location, colour and format? | F39: Pass | G39: Empty password: the browser stopped me and said "Please fill out this field.". Wrong password: a red "Invalid credentials" message showed just above the Sign in button after I clicked it. | K39: Compatibility Testing Evidence/chrome-invalid-login.png | L39: 2.83
C40: 28 | D40: Forms | E40: When placeholder text is included in each form field, is the text: - Visible - Understandable - Rendered in the correct colour (i.e. to differentiate from user inputs) | F40: Pass | G40: When the student list can't load, the Student box shows the placeholder "e.g. S001" in grey, so it looks different from real typed text. Easy to understand. | K40: Compatibility Testing Evidence/chrome-placeholder.png | L40: 0.27
C41: 29 | D41: Forms | E41: Do form fields auto-complete correctly, using data previously saved by the browser? | F41: Not run | G41: The password box is set up for autofill (autocomplete="current-password"), but the test browser has no saved passwords so I couldn't try it.
C42: 30 | D42: Forms | E42: When the user submits a form (e.g. by clicking Save, Submit or OK): - Is a visual indicator displayed to indicate that the form is saving (e.g. spinning wheel or progress bar)? - After the form is saved/submitted, does an appropriate success message appear? - Is the success message in the correct location, format and colour? | F42: Pass | G42: Login form: the button changes to "Signing in…" while it works and then the dashboard opens with "Hi Chloe". "Generate my study plan" also shows "Generating..." and then my personalised study plan appears for each knowledge gap. (This failed in my first test run - see DEF-02. After the fix I retested it and it passed.) | H42: DEF-02 | I42: Minor | J42: AI study plan can't be generated: the server returns an error because no GROQ_API_KEY is configured on Render. Same on every system. This is a configuration issue (missing setting), not a bug in the code. Fixed: GROQ_API_KEY added to the backend on Render. Retested 05/10/2026: Pass. | K42: After fix: Compatibility Testing Evidence/chrome-ai-study-plan.png Before fix: Compatibility Testing Evidence/first-run/chrome-ai-study-plan-error.png | L42: 7.66
C43: 31 | D43: Interactions | E43: Do mouse inputs work correctly, including: - Hover over (e.g. display tool tip text) - Right mouse button click - Left mouse button click - Scroll wheel - Programmable mouse buttons - Any other mouse buttons | F43: Pass | G43: Hovering over the Sign in button makes it lighter. Left click works on all buttons. The scroll wheel scrolls the dashboard. Right click opens the normal browser menu. (No tooltips in our app.) | L43: 4.66
C44: 32 | D44: Interactions | E44: Do keyboard inputs work correctly, including: - Letters - Numbers - Symbols - Function keys (F1 to F12) - Control keys (e.g. escape, control, command (Apple Mac) alt, shift, tab, print screen, enter, shift lock, num lock, etc.) - Navigation keys (arrow keys, home, end, page up, page down) | F44: Pass | G44: Tab moved from the dropdown to the password box. Letters, numbers and symbols typed fine, Backspace worked and Enter logged me in. Function keys aren't used by our app. | L44: 3.26
...

Sheet Firefox (macOS)
C3: Compatibility Testing Checklist
D5: Test object: | E5: Learning Journey Assistant (https://learning-journey-app.onrender.com) | F5: Name of the system being tested
D6: Test basis: | E6: User stories: a student logs in and views their mastery scores, knowledge gaps, feedback history and AI study plan. Also past experience with similar web apps. | F6: What test design is based on - for example, requirements, epics, user stories, or past experience with similar systems
D7: Page name: | E7: Login page and Student Dashboard | F7: Name of the page or tab being tested
D8: Environment details: | E8: MacBook, macOS 26.5.2, Mozilla Firefox 155.0 (Playwright build), screen 1440x900. Tests run with a Playwright automation script. | F8: Describe the test environment - e.g. Apple iPhone X running iOS Y, Edge browser version aa.bb
D9: Tester name: | E9: Ritik Rayamajhi | F9: Name of the person performing the testing
D10: Date tested: | E10: 46300 | F10: Date tests were run on
C12: ID | D12: Perspective | E12: Checklist | F12: Result | G12: Comments | H12: Defect ID | I12: Defect Severity | J12: Defect Details | K12: Test Evidence | L12: Time Taken (sec)
C13: 1 | D13: Page structure | E13: Has the correct page template, style sheet and/or structure been used, matching company and project requirements? | F13: Pass | G13: Both pages (login and dashboard) use the same layout: logo at the top, white rounded cards on a light grey background. | K13: Compatibility Testing Evidence/firefox-dashboard.png | L13: 4.4
C14: 2 | D14: Page structure | E14: Do page colours and fonts match company branding? | F14: Pass | G14: We don't have an official brand guide, so I checked the purple colour is the same on all buttons and the logo on both pages. It matched. | L14: 3.66
C15: 3 | D15: Page structure | E15: Does the page description (e.g. in the title bar or tab) correctly reflect the page content? | F15: Pass | G15: The tab title says "Learning Journey Assistant" on both pages, which matches the app name. | L15: 3.65
C16: 4 | D16: Page structure | E16: Have correct and consistent fonts, text sizes and text positions been used, including: - Header - Menu bar - Body/content - Input and output fields - Buttons (e.g. Next/Previous, Submit/Cancel etc.) - Footer | F16: Pass | G16: Header, body text, dropdown, password box and buttons all use the same font (Geist). Headings are bigger and bold, body text is smaller. Nothing overlapped. (No menu bar or footer in our app.) | L16: 3.74
C17: 5 | D17: Page structure | E17: Does the page display correctly across different screen resolutions, including: - High definition (HD) - Recommended display setting (on computer) - Lowest display setting (on computer) - Devices (e.g. mobile, tablet, watch) | F17: Pass | G17: Checked the dashboard at 1920x1080 (HD), 1440x900 (recommended on this Mac) and 1366x768 / 1024x768 (lowest). It looked fine at all of them. Phones are tested on the mobile sheets. | K17: Compatibility Testing Evidence/firefox-resolution-small.png | L17: 4.23
C18: 6 | D18: Page structure | E18: Does the page scroll smoothly without lagging? | F18: Pass | G18: Scrolled from the top to the bottom of the dashboard. It was smooth with no lag (about 123 frames per second). | L18: 4.31
C19: 7 | D19: Page structure | E19: Is the page content viewable without the need for a horizontal scroll bar? (horizontal scrolling is generally not recommended/preferred) | F19: Pass | G19: No horizontal scroll bar on the login page or the dashboard. Everything fits the width of the screen. | L19: 4.28
C20: 8 | D20: Page structure | E20: Do menus function correctly when opened, traversed and activated/clicked, including: - Hamburger menu - Expandable menus - Collapsible menus - Drop down "more information" menus (usually available via an ellipsis …) | F20: Pass | G20: Our app has no hamburger or expandable menus. The only menu is the student dropdown on the login page - I picked all 5 students one by one and each one got selected. | L20: 0.97
C21: 9 | D21: Page structure | E21: Does the page view correctly when using zoom in and out? | F21: Pass | G21: Zoomed in to 200% and out to 50%. The text and bars resized properly and nothing went off the screen. | K21: Compatibility Testing Evidence/firefox-zoom-200.png | L21: 3.77
C22: 10 | D22: Page structure | E22: When JavaScript is turned off, do understandable error messages appear explaining that JavaScript must be enabled to display required content, without any scripts being displayed to on the screen? | F22: Pass | G22: With JavaScript off the page shows: "Learning Journey Assistant Please enable JavaScript in your browser to use this" (This failed in my first test run - see DEF-01. After the fix I retested it and it passed.) | H22: DEF-01 | I22: Minor | J22: With JavaScript disabled the app shows a blank white page and no message. Expected: a message like "Please enable JavaScript to use this app" (e.g. a <noscript> tag in layout.tsx). Fixed: added a message telling users to turn on JavaScript. Retested 05/10/2026: Pass. | K22: After fix: Compatibility Testing Evidence/firefox-javascript-off.png Before fix: Compatibility Testing Evidence/first-run/firefox-javascript-off.png | L22: 2.14
C23: 11 | D23: Images | E23: Are images displayed correctly, including: - Position on the page (alignment, not overlapping fields, content or edge of screen) - Rendering - Resolution - Background (e.g. transparent) - Lazy loading (load on scroll) - No distortion (i.e. correct aspect ratio) - No broken links | F23: Not applicable | G23: Our pages don't have any images. The logo is just the letters "LJ" in a purple box (made with text, not an image).
C24: 12 | D24: Images | E24: Are images suitable for the given content and context? | F24: Not applicable | G24: No images on the login page or dashboard.
C25: 13 | D25: Images | E25: Do images include suitable alternative text? | F25: Not applicable | G25: No images, so there is no alt text to check.
C26: 14 | D26: Images | E26: Do clickable images navigate to the correct location? | F26: Not applicable | G26: No clickable images in the app.
C27: 15 | D27: Images | E27: Do images display correctly when screen is zoomed in and out? | F27: Not applicable | G27: No images. (Zoom for the rest of the page was checked in test 9.)
C28: 16 | D28: Images | E28: Do animated behaviours display correctly (e.g. Giff) | F28: Not applicable | G28: No GIFs or animations in the app.
C29: 17 | D29: Videos | E29: Are videos displayed, positioned and rendered correctly on the page, with the correct thumbnails? | F29: Not applicable | G29: The app doesn't have any videos.
C30: 18 | D30: Videos | E30: Do videos play correctly, including (where required): - Auto play - Click to play - Tap to play - Picture in picture (PiP) | F30: Not applicable | G30: The app doesn't have any videos.
C31: 19 | D31: Videos | E31: Do videos display with the correct defaults (e.g. auto-play, display inline or full screen) | F31: Not applicable | G31: The app doesn't have any videos.
C32: 20 | D32: Videos | E32: Do all videos display suitable captions, including: - Captions that match the video content - Language preferences - Location on screen | F32: Not applicable | G32: The app doesn't have any videos.
C33: 21 | D33: Videos | E33: Can videos be moved to: - Full screen mode - Embedded/inline mode - Press escape from full-screen mode to revert back to inline mode | F33: Not applicable | G33: The app doesn't have any videos.
C34: 22 | D34: Videos | E34: Do video controls work, including: - Play, pause, stop - Fast forward and rewind (including skip X seconds forward/back) - Volume - Mute/unmute - Playback speed (e.g. 0.5x, 1.5x, 2x) - Resume from last position - Download / long-press - Streaming vs. offline view | F34: Not applicable | G34: The app doesn't have any videos.
C35: 23 | D35: Forms | E35: Are all required fields visible on the form? | F35: Pass | G35: The login form shows both fields I need (Student dropdown and Password) and the Sign in button. All visible without scrolling. | K35: Compatibility Testing Evidence/firefox-login.png | L35: 1.05
C36: 24 | D36: Forms | E36: Are all form fields positioned within the boundaries of the form, and not overlapping or truncating, including: - Labels - Single line textboxes - Multi-line textboxes - Dropdown lists - Radio buttons - Checkboxes - Date pickers - Tables - Grids - Menus and submenus - Images - Drag and drop | F36: Pass | G36: Labels, the dropdown, the password box and the button all sit inside the white form box. Nothing overlaps or gets cut off. | L36: 0.92
C37: 25 | D37: Forms | E37: Does tool tip text display correctly for each field, including: - Single line textboxes - Multi-line textboxes - Dropdown lists - Radio buttons - Checkboxes - Date pickers - Tables - Grids - Drag and drop | F37: Not applicable | G37: Our form fields don't have tooltips. Each field has a label above it instead ("Student", "Password").
C38: 26 | D38: Forms | E38: Can data be input into each field correctly, including: - Single line textboxes - Multi-line textboxes - Dropdown lists - Radio buttons - Checkboxes - Date pickers - Tables - Grids - Drag and drop - Copy/paste | F38: Pass | G38: Picked a student from the dropdown and typed letters, numbers and symbols in the password box. Both worked and the password showed as dots. (Didn't test copy/paste because browsers block copying out of password boxes.) | L38: 1.01
C39: 27 | D39: Forms | E39: When invalid/negative data is input into a field: - Are understandable error messages displayed? - Are error messages displayed at the right time (e.g. when focus leaves the field, or on save)? - Are error messages positioned in the correct location? - Are error validation icons (e.g. ticks, crosses) displayed in the correct location, colour and format? | F39: Pass | G39: Empty password: the browser stopped me and said "Please fill out this field.". Wrong password: a red "Invalid credentials" message showed just above the Sign in button after I clicked it. | K39: Compatibility Testing Evidence/firefox-invalid-login.png | L39: 2.38
C40: 28 | D40: Forms | E40: When placeholder text is included in each form field, is the text: - Visible - Understandable - Rendered in the correct colour (i.e. to differentiate from user inputs) | F40: Pass | G40: When the student list can't load, the Student box shows the placeholder "e.g. S001" in grey, so it looks different from real typed text. Easy to understand. | K40: Compatibility Testing Evidence/firefox-placeholder.png | L40: 0.23
C41: 29 | D41: Forms | E41: Do form fields auto-complete correctly, using data previously saved by the browser? | F41: Not run | G41: The password box is set up for autofill (autocomplete="current-password"), but the test browser has no saved passwords so I couldn't try it.
C42: 30 | D42: Forms | E42: When the user submits a form (e.g. by clicking Save, Submit or OK): - Is a visual indicator displayed to indicate that the form is saving (e.g. spinning wheel or progress bar)? - After the form is saved/submitted, does an appropriate success message appear? - Is the success message in the correct location, format and colour? | F42: Pass | G42: Login form: the button changes to "Signing in…" while it works and then the dashboard opens with "Hi Chloe". "Generate my study plan" also shows "Generating..." and then my personalised study plan appears for each knowledge gap. (This failed in my first test run - see DEF-02. After the fix I retested it and it passed.) | H42: DEF-02 | I42: Minor | J42: AI study plan can't be generated: the server returns an error because no GROQ_API_KEY is configured on Render. Same on every system. This is a configuration issue (missing setting), not a bug in the code. Fixed: GROQ_API_KEY added to the backend on Render. Retested 05/10/2026: Pass. | K42: After fix: Compatibility Testing Evidence/firefox-ai-study-plan.png Before fix: Compatibility Testing Evidence/first-run/firefox-ai-study-plan-error.png | L42: 9.27
C43: 31 | D43: Interactions | E43: Do mouse inputs work correctly, including: - Hover over (e.g. display tool tip text) - Right mouse button click - Left mouse button click - Scroll wheel - Programmable mouse buttons - Any other mouse buttons | F43: Pass | G43: Hovering over the Sign in button makes it lighter. Left click works on all buttons. The scroll wheel scrolls the dashboard. Right click opens the normal browser menu. (No tooltips in our app.) | L43: 4.19
C44: 32 | D44: Interactions | E44: Do keyboard inputs work correctly, including: - Letters - Numbers - Symbols - Function keys (F1 to F12) - Control keys (e.g. escape, control, command (Apple Mac) alt, shift, tab, print screen, enter, shift lock, num lock, etc.) - Navigation keys (arrow keys, home, end, page up, page down) | F44: Pass | G44: Tab moved from the dropdown to the password box. Letters, numbers and symbols typed fine, Backspace worked and Enter logged me in. Function keys aren't used by our app. | L44: 3.28
...

Sheet Safari (macOS)
C3: Compatibility Testing Checklist
D5: Test object: | E5: Learning Journey Assistant (https://learning-journey-app.onrender.com) | F5: Name of the system being tested
D6: Test basis: | E6: User stories: a student logs in and views their mastery scores, knowledge gaps, feedback history and AI study plan. Also past experience with similar web apps. | F6: What test design is based on - for example, requirements, epics, user stories, or past experience with similar systems
D7: Page name: | E7: Login page and Student Dashboard | F7: Name of the page or tab being tested
D8: Environment details: | E8: MacBook, macOS 26.5.2, Safari engine WebKit 26.6 (Playwright build), screen 1440x900. Tests run with a Playwright automation script. | F8: Describe the test environment - e.g. Apple iPhone X running iOS Y, Edge browser version aa.bb
D9: Tester name: | E9: Ritik Rayamajhi | F9: Name of the person performing the testing
D10: Date tested: | E10: 46300 | F10: Date tests were run on
C12: ID | D12: Perspective | E12: Checklist | F12: Result | G12: Comments | H12: Defect ID | I12: Defect Severity | J12: Defect Details | K12: Test Evidence | L12: Time Taken (sec)
C13: 1 | D13: Page structure | E13: Has the correct page template, style sheet and/or structure been used, matching company and project requirements? | F13: Pass | G13: Both pages (login and dashboard) use the same layout: logo at the top, white rounded cards on a light grey background. | K13: Compatibility Testing Evidence/safari-dashboard.png | L13: 3.76
C14: 2 | D14: Page structure | E14: Do page colours and fonts match company branding? | F14: Pass | G14: We don't have an official brand guide, so I checked the purple colour is the same on all buttons and the logo on both pages. It matched. | L14: 3.81
C15: 3 | D15: Page structure | E15: Does the page description (e.g. in the title bar or tab) correctly reflect the page content? | F15: Pass | G15: The tab title says "Learning Journey Assistant" on both pages, which matches the app name. | L15: 3.63
C16: 4 | D16: Page structure | E16: Have correct and consistent fonts, text sizes and text positions been used, including: - Header - Menu bar - Body/content - Input and output fields - Buttons (e.g. Next/Previous, Submit/Cancel etc.) - Footer | F16: Pass | G16: Header, body text, dropdown, password box and buttons all use the same font (Geist). Headings are bigger and bold, body text is smaller. Nothing overlapped. (No menu bar or footer in our app.) | L16: 3.66
C17: 5 | D17: Page structure | E17: Does the page display correctly across different screen resolutions, including: - High definition (HD) - Recommended display setting (on computer) - Lowest display setting (on computer) - Devices (e.g. mobile, tablet, watch) | F17: Pass | G17: Checked the dashboard at 1920x1080 (HD), 1440x900 (recommended on this Mac) and 1366x768 / 1024x768 (lowest). It looked fine at all of them. Phones are tested on the mobile sheets. | K17: Compatibility Testing Evidence/safari-resolution-small.png | L17: 4.2
C18: 6 | D18: Page structure | E18: Does the page scroll smoothly without lagging? | F18: Pass | G18: Scrolled from the top to the bottom of the dashboard. It was smooth with no lag (about 63 frames per second). | L18: 4.82
C19: 7 | D19: Page structure | E19: Is the page content viewable without the need for a horizontal scroll bar? (horizontal scrolling is generally not recommended/preferred) | F19: Pass | G19: No horizontal scroll bar on the login page or the dashboard. Everything fits the width of the screen. | L19: 3.64
C20: 8 | D20: Page structure | E20: Do menus function correctly when opened, traversed and activated/clicked, including: - Hamburger menu - Expandable menus - Collapsible menus - Drop down "more information" menus (usually available via an ellipsis …) | F20: Pass | G20: Our app has no hamburger or expandable menus. The only menu is the student dropdown on the login page - I picked all 5 students one by one and each one got selected. | L20: 0.97
C21: 9 | D21: Page structure | E21: Does the page view correctly when using zoom in and out? | F21: Pass | G21: Zoomed in to 200% and out to 50%. The text and bars resized properly and nothing went off the screen. | K21: Compatibility Testing Evidence/safari-zoom-200.png | L21: 4.48
C22: 10 | D22: Page structure | E22: When JavaScript is turned off, do understandable error messages appear explaining that JavaScript must be enabled to display required content, without any scripts being displayed to on the screen? | F22: Pass | G22: With JavaScript off the page shows: "Learning Journey Assistant Please enable JavaScript in your browser to use this" (This failed in my first test run - see DEF-01. After the fix I retested it and it passed.) | H22: DEF-01 | I22: Minor | J22: With JavaScript disabled the app shows a blank white page and no message. Expected: a message like "Please enable JavaScript to use this app" (e.g. a <noscript> tag in layout.tsx). Fixed: added a message telling users to turn on JavaScript. Retested 05/10/2026: Pass. | K22: After fix: Compatibility Testing Evidence/safari-javascript-off.png Before fix: Compatibility Testing Evidence/first-run/safari-javascript-off.png | L22: 1.71
C23: 11 | D23: Images | E23: Are images displayed correctly, including: - Position on the page (alignment, not overlapping fields, content or edge of screen) - Rendering - Resolution - Background (e.g. transparent) - Lazy loading (load on scroll) - No distortion (i.e. correct aspect ratio) - No broken links | F23: Not applicable | G23: Our pages don't have any images. The logo is just the letters "LJ" in a purple box (made with text, not an image).
C24: 12 | D24: Images | E24: Are images suitable for the given content and context? | F24: Not applicable | G24: No images on the login page or dashboard.
C25: 13 | D25: Images | E25: Do images include suitable alternative text? | F25: Not applicable | G25: No images, so there is no alt text to check.
C26: 14 | D26: Images | E26: Do clickable images navigate to the correct location? | F26: Not applicable | G26: No clickable images in the app.
C27: 15 | D27: Images | E27: Do images display correctly when screen is zoomed in and out? | F27: Not applicable | G27: No images. (Zoom for the rest of the page was checked in test 9.)
C28: 16 | D28: Images | E28: Do animated behaviours display correctly (e.g. Giff) | F28: Not applicable | G28: No GIFs or animations in the app.
C29: 17 | D29: Videos | E29: Are videos displayed, positioned and rendered correctly on the page, with the correct thumbnails? | F29: Not applicable | G29: The app doesn't have any videos.
C30: 18 | D30: Videos | E30: Do videos play correctly, including (where required): - Auto play - Click to play - Tap to play - Picture in picture (PiP) | F30: Not applicable | G30: The app doesn't have any videos.
C31: 19 | D31: Videos | E31: Do videos display with the correct defaults (e.g. auto-play, display inline or full screen) | F31: Not applicable | G31: The app doesn't have any videos.
C32: 20 | D32: Videos | E32: Do all videos display suitable captions, including: - Captions that match the video content - Language preferences - Location on screen | F32: Not applicable | G32: The app doesn't have any videos.
C33: 21 | D33: Videos | E33: Can videos be moved to: - Full screen mode - Embedded/inline mode - Press escape from full-screen mode to revert back to inline mode | F33: Not applicable | G33: The app doesn't have any videos.
C34: 22 | D34: Videos | E34: Do video controls work, including: - Play, pause, stop - Fast forward and rewind (including skip X seconds forward/back) - Volume - Mute/unmute - Playback speed (e.g. 0.5x, 1.5x, 2x) - Resume from last position - Download / long-press - Streaming vs. offline view | F34: Not applicable | G34: The app doesn't have any videos.
C35: 23 | D35: Forms | E35: Are all required fields visible on the form? | F35: Pass | G35: The login form shows both fields I need (Student dropdown and Password) and the Sign in button. All visible without scrolling. | K35: Compatibility Testing Evidence/safari-login.png | L35: 1.03
C36: 24 | D36: Forms | E36: Are all form fields positioned within the boundaries of the form, and not overlapping or truncating, including: - Labels - Single line textboxes - Multi-line textboxes - Dropdown lists - Radio buttons - Checkboxes - Date pickers - Tables - Grids - Menus and submenus - Images - Drag and drop | F36: Pass | G36: Labels, the dropdown, the password box and the button all sit inside the white form box. Nothing overlaps or gets cut off. | L36: 0.92
C37: 25 | D37: Forms | E37: Does tool tip text display correctly for each field, including: - Single line textboxes - Multi-line textboxes - Dropdown lists - Radio buttons - Checkboxes - Date pickers - Tables - Grids - Drag and drop | F37: Not applicable | G37: Our form fields don't have tooltips. Each field has a label above it instead ("Student", "Password").
C38: 26 | D38: Forms | E38: Can data be input into each field correctly, including: - Single line textboxes - Multi-line textboxes - Dropdown lists - Radio buttons - Checkboxes - Date pickers - Tables - Grids - Drag and drop - Copy/paste | F38: Pass | G38: Picked a student from the dropdown and typed letters, numbers and symbols in the password box. Both worked and the password showed as dots. (Didn't test copy/paste because browsers block copying out of password boxes.) | L38: 0.98
C39: 27 | D39: Forms | E39: When invalid/negative data is input into a field: - Are understandable error messages displayed? - Are error messages displayed at the right time (e.g. when focus leaves the field, or on save)? - Are error messages positioned in the correct location? - Are error validation icons (e.g. ticks, crosses) displayed in the correct location, colour and format? | F39: Pass | G39: Empty password: the browser stopped me and said "Fill out this field". Wrong password: a red "Invalid credentials" message showed just above the Sign in button after I clicked it. | K39: Compatibility Testing Evidence/safari-invalid-login.png | L39: 2.29
C40: 28 | D40: Forms | E40: When placeholder text is included in each form field, is the text: - Visible - Understandable - Rendered in the correct colour (i.e. to differentiate from user inputs) | F40: Pass | G40: When the student list can't load, the Student box shows the placeholder "e.g. S001" in grey, so it looks different from real typed text. Easy to understand. | K40: Compatibility Testing Evidence/safari-placeholder.png | L40: 0.15
C41: 29 | D41: Forms | E41: Do form fields auto-complete correctly, using data previously saved by the browser? | F41: Not run | G41: The password box is set up for autofill (autocomplete="current-password"), but the test browser has no saved passwords so I couldn't try it.
C42: 30 | D42: Forms | E42: When the user submits a form (e.g. by clicking Save, Submit or OK): - Is a visual indicator displayed to indicate that the form is saving (e.g. spinning wheel or progress bar)? - After the form is saved/submitted, does an appropriate success message appear? - Is the success message in the correct location, format and colour? | F42: Pass | G42: Login form: the button changes to "Signing in…" while it works and then the dashboard opens with "Hi Chloe". "Generate my study plan" also shows "Generating..." and then my personalised study plan appears for each knowledge gap. (This failed in my first test run - see DEF-02. After the fix I retested it and it passed.) | H42: DEF-02 | I42: Minor | J42: AI study plan can't be generated: the server returns an error because no GROQ_API_KEY is configured on Render. Same on every system. This is a configuration issue (missing setting), not a bug in the code. Fixed: GROQ_API_KEY added to the backend on Render. Retested 05/10/2026: Pass. | K42: After fix: Compatibility Testing Evidence/safari-ai-study-plan.png Before fix: Compatibility Testing Evidence/first-run/safari-ai-study-plan-error.png | L42: 9.67
C43: 31 | D43: Interactions | E43: Do mouse inputs work correctly, including: - Hover over (e.g. display tool tip text) - Right mouse button click - Left mouse button click - Scroll wheel - Programmable mouse buttons - Any other mouse buttons | F43: Pass | G43: Hovering over the Sign in button makes it lighter. Left click works on all buttons. The scroll wheel scrolls the dashboard. Right click opens the normal browser menu. (No tooltips in our app.) | L43: 4.14
C44: 32 | D44: Interactions | E44: Do keyboard inputs work correctly, including: - Letters - Numbers - Symbols - Function keys (F1 to F12) - Control keys (e.g. escape, control, command (Apple Mac) alt, shift, tab, print screen, enter, shift lock, num lock, etc.) - Navigation keys (arrow keys, home, end, page up, page down) | F44: Pass | G44: Tab moved from the dropdown to the password box. Letters, numbers and symbols typed fine, Backspace worked and Enter logged me in. Function keys aren't used by our app. | L44: 3.34
...

Sheet iPhone 13 (Safari)
C3: Compatibility Testing Checklist
D5: Test object: | E5: Learning Journey Assistant (https://learning-journey-app.onrender.com) | F5: Name of the system being tested
D6: Test basis: | E6: User stories: a student logs in and views their mastery scores, knowledge gaps, feedback history and AI study plan. Also past experience with similar web apps. | F6: What test design is based on - for example, requirements, epics, user stories, or past experience with similar systems
D7: Page name: | E7: Login page and Student Dashboard | F7: Name of the page or tab being tested
D8: Environment details: | E8: Apple iPhone 13 emulator (iOS Safari, WebKit 26.6) on macOS, screen 390x664, touch on. Tests run with a Playwright automation script. | F8: Describe the test environment - e.g. Apple iPhone X running iOS Y, Edge browser version aa.bb
D9: Tester name: | E9: Ritik Rayamajhi | F9: Name of the person performing the testing
D10: Date tested: | E10: 46300 | F10: Date tests were run on
C12: ID | D12: Perspective | E12: Checklist | F12: Result | G12: Comments | H12: Defect ID | I12: Defect Severity | J12: Defect Details | K12: Test Evidence | L12: Time Taken (sec)
C13: 1 | D13: Page structure | E13: Has the correct page template, style sheet and/or structure been used, matching company and project requirements? | F13: Pass | G13: Both pages (login and dashboard) use the same layout: logo at the top, white rounded cards on a light grey background. | K13: Compatibility Testing Evidence/iphone-dashboard.png | L13: 3.89
C14: 2 | D14: Page structure | E14: Do page colours and fonts match company branding? | F14: Pass | G14: We don't have an official brand guide, so I checked the purple colour is the same on all buttons and the logo on both pages. It matched. | L14: 4.25
C15: 3 | D15: Page structure | E15: Does the page description (e.g. in the title bar or tab) correctly reflect the page content? | F15: Pass | G15: The tab title says "Learning Journey Assistant" on both pages, which matches the app name. | L15: 4.74
C16: 4 | D16: Page structure | E16: Have correct and consistent fonts, text sizes and text positions been used, including: - Header - Menu bar - Body/content - Input and output fields - Buttons (e.g. Next/Previous, Submit/Cancel etc.) - Footer | F16: Pass | G16: Header, body text, dropdown, password box and buttons all use the same font (Geist). Headings are bigger and bold, body text is smaller. Nothing overlapped. (No menu bar or footer in our app.) | L16: 4.19
C17: 5 | D17: Page structure | E17: Does the page display correctly across different screen resolutions, including: - High definition (HD) - Recommended display setting (on computer) - Lowest display setting (on computer) - Devices (e.g. mobile, tablet, watch) | F17: Pass | G17: Checked the dashboard in portrait (390x664) and landscape (664x390). It fit the screen both ways. | K17: Compatibility Testing Evidence/iphone-resolution-small.png | L17: 3.74
C18: 6 | D18: Page structure | E18: Does the page scroll smoothly without lagging? | F18: Pass | G18: Scrolled from the top to the bottom of the dashboard. It was smooth with no lag (about 62 frames per second). | L18: 4.3
C19: 7 | D19: Page structure | E19: Is the page content viewable without the need for a horizontal scroll bar? (horizontal scrolling is generally not recommended/preferred) | F19: Pass | G19: No horizontal scroll bar on the login page or the dashboard. Everything fits the width of the screen. | L19: 4.16
C20: 8 | D20: Page structure | E20: Do menus function correctly when opened, traversed and activated/clicked, including: - Hamburger menu - Expandable menus - Collapsible menus - Drop down "more information" menus (usually available via an ellipsis …) | F20: Pass | G20: Our app has no hamburger or expandable menus. The only menu is the student dropdown on the login page - I picked all 5 students one by one and each one got selected. | L20: 0.93
C21: 9 | D21: Page structure | E21: Does the page view correctly when using zoom in and out? | F21: Pass | G21: Zoomed in to 200% and out to 50%. The text and bars resized properly and nothing went off the screen. (This failed in my first test run - see DEF-03. After the fix I retested it and it passed.) | H21: DEF-03 | I21: Minor | J21: On iPhone at 200% page zoom (very narrow screen, ~195px), the score labels in 'Mastery by learning outcome' overflow the right edge and cause sideways scrolling. Fix: let the label wrap under the outcome text on very small screens. Fixed: text and score labels now wrap on very narrow screens. Retested 05/10/2026: Pass. | K21: After fix: Compatibility Testing Evidence/iphone-zoom-200.png Before fix: Compatibility Testing Evidence/first-run/iphone-zoom-200.png | L21: 4.25
C22: 10 | D22: Page structure | E22: When JavaScript is turned off, do understandable error messages appear explaining that JavaScript must be enabled to display required content, without any scripts being displayed to on the screen? | F22: Pass | G22: With JavaScript off the page shows: "Learning Journey Assistant Please enable JavaScript in your browser to use this" (This failed in my first test run - see DEF-01. After the fix I retested it and it passed.) | H22: DEF-01 | I22: Minor | J22: With JavaScript disabled the app shows a blank white page and no message. Expected: a message like "Please enable JavaScript to use this app" (e.g. a <noscript> tag in layout.tsx). Fixed: added a message telling users to turn on JavaScript. Retested 05/10/2026: Pass. | K22: After fix: Compatibility Testing Evidence/iphone-javascript-off.png Before fix: Compatibility Testing Evidence/first-run/iphone-javascript-off.png | L22: 1.71
C23: 11 | D23: Images | E23: Are images displayed correctly, including: - Position on the page (alignment, not overlapping fields, content or edge of screen) - Rendering - Resolution - Background (e.g. transparent) - Lazy loading (load on scroll) - No distortion (i.e. correct aspect ratio) - No broken links | F23: Not applicable | G23: Our pages don't have any images. The logo is just the letters "LJ" in a purple box (made with text, not an image).
C24: 12 | D24: Images | E24: Are images suitable for the given content and context? | F24: Not applicable | G24: No images on the login page or dashboard.
C25: 13 | D25: Images | E25: Do images include suitable alternative text? | F25: Not applicable | G25: No images, so there is no alt text to check.
C26: 14 | D26: Images | E26: Do clickable images navigate to the correct location? | F26: Not applicable | G26: No clickable images in the app.
C27: 15 | D27: Images | E27: Do images display correctly when screen is zoomed in and out? | F27: Not applicable | G27: No images. (Zoom for the rest of the page was checked in test 9.)
C28: 16 | D28: Images | E28: Do animated behaviours display correctly (e.g. Giff) | F28: Not applicable | G28: No GIFs or animations in the app.
C29: 17 | D29: Videos | E29: Are videos displayed, positioned and rendered correctly on the page, with the correct thumbnails? | F29: Not applicable | G29: The app doesn't have any videos.
C30: 18 | D30: Videos | E30: Do videos play correctly, including (where required): - Auto play - Click to play - Tap to play - Picture in picture (PiP) | F30: Not applicable | G30: The app doesn't have any videos.
C31: 19 | D31: Videos | E31: Do videos display with the correct defaults (e.g. auto-play, display inline or full screen) | F31: Not applicable | G31: The app doesn't have any videos.
C32: 20 | D32: Videos | E32: Do all videos display suitable captions, including: - Captions that match the video content - Language preferences - Location on screen | F32: Not applicable | G32: The app doesn't have any videos.
C33: 21 | D33: Videos | E33: Can videos be moved to: - Full screen mode - Embedded/inline mode - Press escape from full-screen mode to revert back to inline mode | F33: Not applicable | G33: The app doesn't have any videos.
C34: 22 | D34: Videos | E34: Do video controls work, including: - Play, pause, stop - Fast forward and rewind (including skip X seconds forward/back) - Volume - Mute/unmute - Playback speed (e.g. 0.5x, 1.5x, 2x) - Resume from last position - Download / long-press - Streaming vs. offline view | F34: Not applicable | G34: The app doesn't have any videos.
C35: 23 | D35: Forms | E35: Are all required fields visible on the form? | F35: Pass | G35: The login form shows both fields I need (Student dropdown and Password) and the Sign in button. All visible without scrolling. | K35: Compatibility Testing Evidence/iphone-login.png | L35: 0.95
C36: 24 | D36: Forms | E36: Are all form fields positioned within the boundaries of the form, and not overlapping or truncating, including: - Labels - Single line textboxes - Multi-line textboxes - Dropdown lists - Radio buttons - Checkboxes - Date pickers - Tables - Grids - Menus and submenus - Images - Drag and drop | F36: Pass | G36: Labels, the dropdown, the password box and the button all sit inside the white form box. Nothing overlaps or gets cut off. | L36: 0.92
C37: 25 | D37: Forms | E37: Does tool tip text display correctly for each field, including: - Single line textboxes - Multi-line textboxes - Dropdown lists - Radio buttons - Checkboxes - Date pickers - Tables - Grids - Drag and drop | F37: Not applicable | G37: Our form fields don't have tooltips. Each field has a label above it instead ("Student", "Password").
C38: 26 | D38: Forms | E38: Can data be input into each field correctly, including: - Single line textboxes - Multi-line textboxes - Dropdown lists - Radio buttons - Checkboxes - Date pickers - Tables - Grids - Drag and drop - Copy/paste | F38: Pass | G38: Picked a student from the dropdown and typed letters, numbers and symbols in the password box. Both worked and the password showed as dots. (Didn't test copy/paste because browsers block copying out of password boxes.) | L38: 0.96
C39: 27 | D39: Forms | E39: When invalid/negative data is input into a field: - Are understandable error messages displayed? - Are error messages displayed at the right time (e.g. when focus leaves the field, or on save)? - Are error messages positioned in the correct location? - Are error validation icons (e.g. ticks, crosses) displayed in the correct location, colour and format? | F39: Pass | G39: Empty password: the browser stopped me and said "Fill out this field". Wrong password: a red "Invalid credentials" message showed just above the Sign in button after I clicked it. | K39: Compatibility Testing Evidence/iphone-invalid-login.png | L39: 2.36
C40: 28 | D40: Forms | E40: When placeholder text is included in each form field, is the text: - Visible - Understandable - Rendered in the correct colour (i.e. to differentiate from user inputs) | F40: Pass | G40: When the student list can't load, the Student box shows the placeholder "e.g. S001" in grey, so it looks different from real typed text. Easy to understand. | K40: Compatibility Testing Evidence/iphone-placeholder.png | L40: 0.13
C41: 29 | D41: Forms | E41: Do form fields auto-complete correctly, using data previously saved by the browser? | F41: Not run | G41: The password box is set up for autofill (autocomplete="current-password"), but the test browser has no saved passwords so I couldn't try it.
C42: 30 | D42: Forms | E42: When the user submits a form (e.g. by clicking Save, Submit or OK): - Is a visual indicator displayed to indicate that the form is saving (e.g. spinning wheel or progress bar)? - After the form is saved/submitted, does an appropriate success message appear? - Is the success message in the correct location, format and colour? | F42: Pass | G42: Login form: the button changes to "Signing in…" while it works and then the dashboard opens with "Hi Chloe". "Generate my study plan" also shows "Generating..." and then my personalised study plan appears for each knowledge gap. (This failed in my first test run - see DEF-02. After the fix I retested it and it passed.) | H42: DEF-02 | I42: Minor | J42: AI study plan can't be generated: the server returns an error because no GROQ_API_KEY is configured on Render. Same on every system. This is a configuration issue (missing setting), not a bug in the code. Fixed: GROQ_API_KEY added to the backend on Render. Retested 05/10/2026: Pass. | K42: After fix: Compatibility Testing Evidence/iphone-ai-study-plan.png Before fix: Compatibility Testing Evidence/first-run/iphone-ai-study-plan-error.png | L42: 9.16
C43: 31 | D43: Interactions | E43: Do mouse inputs work correctly, including: - Hover over (e.g. display tool tip text) - Right mouse button click - Left mouse button click - Scroll wheel - Programmable mouse buttons - Any other mouse buttons | F43: Not applicable | G43: Phones don't use a mouse. Touch is tested in test 33.
C44: 32 | D44: Interactions | E44: Do keyboard inputs work correctly, including: - Letters - Numbers - Symbols - Function keys (F1 to F12) - Control keys (e.g. escape, control, command (Apple Mac) alt, shift, tab, print screen, enter, shift lock, num lock, etc.) - Navigation keys (arrow keys, home, end, page up, page down) | F44: Pass | G44: Typed letters, numbers and symbols in the password box with the keyboard, Backspace deleted them, and pressing Enter (Go) logged me in. | L44: 3.86
...

Sheet Pixel 7 (Chrome)
C3: Compatibility Testing Checklist
D5: Test object: | E5: Learning Journey Assistant (https://learning-journey-app.onrender.com) | F5: Name of the system being tested
D6: Test basis: | E6: User stories: a student logs in and views their mastery scores, knowledge gaps, feedback history and AI study plan. Also past experience with similar web apps. | F6: What test design is based on - for example, requirements, epics, user stories, or past experience with similar systems
D7: Page name: | E7: Login page and Student Dashboard | F7: Name of the page or tab being tested
D8: Environment details: | E8: Google Pixel 7 emulator (Android, Chrome 154.0.8037.95) on macOS, screen 412x839, touch on. Tests run with a Playwright automation script. | F8: Describe the test environment - e.g. Apple iPhone X running iOS Y, Edge browser version aa.bb
D9: Tester name: | E9: Ritik Rayamajhi | F9: Name of the person performing the testing
D10: Date tested: | E10: 46300 | F10: Date tests were run on
C12: ID | D12: Perspective | E12: Checklist | F12: Result | G12: Comments | H12: Defect ID | I12: Defect Severity | J12: Defect Details | K12: Test Evidence | L12: Time Taken (sec)
C13: 1 | D13: Page structure | E13: Has the correct page template, style sheet and/or structure been used, matching company and project requirements? | F13: Pass | G13: Both pages (login and dashboard) use the same layout: logo at the top, white rounded cards on a light grey background. | K13: Compatibility Testing Evidence/android-dashboard.png | L13: 3.97
